Workbook

Sheet 刀男所需材料
A1: 类型 | B1: 刀刀 | D1: 稀有度 | E1: 进阶 | F1: 材料 | M1: 贡献者
A2: 合成bug：已有的高级素材在升级合成界面不计入统计，必须一次性用足够的一级素材合成足够的高级素材 | M2: 比如我，纸缺5，需求量10，想着有一把刀快羁绊3了，那... https://xhslink.cn/o/Vg6kGMX6Xy 留住这段口令，去【小红书】瞅瞅笔记~
A3: （例：需求纸10，已有纸8的合成素材和纸5，合成后会变成8/10和5/10，需要刷够纸10的素材合成才能达成10/10） | M3: by小红书@Miyu
A4: 大 太 刀 | B4: 太郎太刀 | D4: 普 | E4: 10->20 | F4: 叶子x2 | G4: 大豆x2 | M4: 神秘的审神者
E5: 20->30 | F5: 臼与杵x2 | G5: 树枝x2 | H5: 大豆x2 | I5: 打火石x2 | M5: 年下阴角激推
E6: 30->35 | F6: 黄色颜料x1 | G6: 茶碗×2 | H6: 围棋x2 | I6: 味增汤x2 | J6: 锄头×2 | K6: 大太刀的心得x1 | M6: 年下阴角激推
D7: 彩 | E7: 10->20 | F7: 桃子x1 | G7: 大豆x1 | M7: lotus
E8: 20->30 | F8: 花蜜x2 | G8: 木材x2 | H8: 大豆x2 | I8: 打火石x2
E9: 30->35 | F9: 黄色颜料x1 | G9: 茶碗x4 | H9: 围棋x2 | I9: 味增汤x2 | J9: 锄头x2 | K9: 大太刀的心得x1 | M9: 金乌
B10: 次郎太刀 | D10: 普 | E10: 10->20 | F10: 水x2 | G10: 木材x2 | M10: 文州
E11: 20->30 | F11: 纸x2 | G11: 蓬松的毛x2 | H11: 水x2 | I11: 花x2 | M11: 文州
E12: 30->35 | F12: 红色颜料x1 | G12: 双六x2 | H12: 花札x2 | I12: 味增汤 | J12: 锄头x2 | K12: 大太刀的心得x1 | M12: piya
B13: 石切丸 | D13: 普 | E13: 10->20 | F13: 叶子x2 | G13: 大豆x2 | M13: rining
E14: 20->30 | F14: 花蜜x2 | G14: 麦x2 | H14: 木材X2 | I14: 树枝x2 | M14: 年下阴角激推
E15: 30->35 | F15: 蓝色颜料×1 | G15: 书写道具×2 | H15: 围棋×2 | I15: 双色牡丹饼×2 | J15: 锄头×2 | K15: 大太刀的心得×1 | M15: 求求你不要再熬夜了
B16: 萤丸 | D16: 普 | E16: 10->20 | F16: 叶子x2 | G16: 大豆x2 | M16: 风骅
E17: 20->30 | F17: 花蜜x2 | G17: 树枝x2 | H17: 蓬松的毛x2 | I17: 大米 | M17: 黄油面包刀
E18: 30->35 | F18: 蓝色颜料x1 | G18: 双六x2 | H18: 围棋x2 | I18: 味增汤x2 | J18: 算盘x2 | K18: 大太刀的心得x1 | M18: 年下阴角激推
A19: 太 刀 | B19: 三日月宗近 | D19: 普 | E19: 10->20 | F19: 水x2 | G19: 蓬松的毛x2
E20: 20->30 | F20: 纸x2 | G20: 蓬松的毛x2 | H20: 水x2 | I20: 花x4 | M20: piya
E21: 30->35 | F21: 黄色颜料x1 | G21: 茶碗x2 | H21: 围棋x2 | I21: 双色牡丹饼x2 | J21: 算盘x2 | K21: 太刀的心得x1
D22: 彩 | E22: 10->20 | F22: 桃子x1 | G22: 水x1 | M22: 方块硫酸银
E23: 20->30 | F23: 纸×2 | G23: 水×4 | H23: 骰子×4 | I23: 花×2 | M23: yukino
E24: 30->35 | F24: 红色颜料x1 | G24: 茶碗x4 | H24: 围棋x2 | I24: 团子x2 | J24: 锄头x2 | K24: 太刀的心得x1 | M24: yui（歇菜版）
B25: 小狐丸 | D25: 普 | E25: 10->20 | F25: 水x2 | G25: 蓬松的毛x2 | M25: lotus
E26: 20->30 | F26: 花蜜x2 | G26: 木材x2 | H26: 水x4 | I26: 树枝x2 | M26: 想有一个糖罐
E27: 30->35 | F27: 红色颜料x1 | G27: 茶碗x2 | H27: 围棋x2 | I27: 双色牡丹饼x2 | J27: 锄头x2 | K27: 太刀的心得x1 | M27: piya
B28: 一期一振 | D28: 普 | E28: 10->20 | F28: 水x2 | G28: 蓬松的毛x2 | M28: 文州
E29: 20->30
E30: 30->35 | F30: 黄色颜料×1 | G30: 双六×2 | H30: 花札×2 | I30: 双色牡丹饼×2 | J30: 算盘×2 | K30: 太刀的心得×1 | M30: yui（歇菜版）
D31: 彩 | E31: 10->20 | F31: 带骨肉×1 | G31: 蓬松的毛×1 | M31: mo陌mo
E32: 20->30 | F32: 花蜜x2 | G32: 大豆x4 | H32: 蓬松的毛x2 | I32: 木材x4 | M32: 方块硫酸银
E33: 30->35 | F33: 黄色颜料x1 | G33: 茶碗x4 | H33: 围棋x2 | I33: 双色牡丹饼x2 | J33: 算盘x2 | K33: 太刀的心得x1 | M33: 金乌
B34: 烛台切光忠 | D34: 普 | E34: 10->20 | F34: 蓬松的毛x2 | G34: 麦x2 | M34: lotus
E35: 20->30
E36: 30->35 | F36: 黄色颜料x1 | G36: 茶碗x2 | H36: 围棋x2 | I36: 双色牡丹饼x2 | J36: 锄头x2 | K36: 太刀的心得x1 | M36: 年下阴角激推
B37: 莺丸 | D37: 普 | E37: 10->20 | F37: 水x2 | G37: 蓬松的毛x2
E38: 20->30 | F38: 纸x2 | G38: 大豆x2 | H38: 蓬松的毛x2 | I38: 花x4 | M38: 年下阴角激推
E39: 30->35 | F39: 蓝色颜料x1 | G39: 茶碗x2 | H39: 围棋x2 | I39: 面包x2 | J39: 算盘x2 | K39: 太刀的心得x1 | M39: 黄油面包刀
B40: 鹤丸国永 | D40: 普 | E40: 10->20 | F40: 水x2 | G40: 蓬松的毛x2 | M40: 风骅
...

Sheet 材料合成
A1: 中文名 | B1: 材料名 | C1: 合成材料 | D1: 数量 | E1: 链接(excel可直接跳转) | G1: 贡献者 | H1: 这里是单个材料的合成数量，游戏里显示是多个的需求量，记得除一下
A2: 合成bug：已有的高级素材在升级合成界面不计入统计，必须一次性用足够的一级素材合成足够的高级素材 | I2: 比如我，纸缺5，需求量10，想着有一把刀快羁绊3了，那... https://xhslink.cn/o/Vg6kGMX6Xy 留住这段口令，去【小红书】瞅瞅笔记~
A3: （例：需求纸10，已有纸8的合成素材和纸5，合成后会变成8/10和5/10，需要刷够纸10的素材合成才能达成10/10） | I3: by小红书@Miyu
A4: 茶碗 | B4: お茶碗 | C4: お椀 | D4: 4 | E4: 合成->
C5: 鉄 | D5: 4 | E5: 前往->
C6: 火打ち石 | D6: 1 | E6: 前往->
C7: 小判 | D7: 150
A8: 围棋 | B8: 囲碁 | C8: 丸太 | D8: 1 | E8: 前往->
C9: 獣の牙 | D9: 1 | E9: 前往->
C10: お椀 | D10: 1 | E10: 合成->
C11: ウロコ | D11: 1 | E11: 前往->
C12: 小判 | D12: 150
A13: 双色牡丹饼 | B13: 二色おはぎ | C13: お米 | D13: 4 | E13: 前往->
C14: 塩 | D14: 1 | E14: 前往->
C15: 大豆 | D15: 1 | E15: 前往->
C16: 花の蜜 | D16: 1 | E16: 合成->
C17: 小判 | D17: 50
A18: 算盘 | B18: そろばん | C18: とんかち | D18: 5 | E18: 合成->
C19: 鉄 | D19: 3 | E19: 前往->
C20: 木の枝 | D20: 1 | E20: 前往->
C21: 丸太 | D21: 1 | E21: 前往->
C22: 小判 | D22: 50
A23: 太刀的心得 | B23: 太刀の心得 | C23: 紙 | D23: 6 | E23: 合成->
C24: 筆 | D24: 6 | E24: 合成->
C25: みかげ石 | D25: 6 | E25: 前往->
C26: 小判 | D26: 150
A27: 花札 | B27: 花札 | C27: 紙 | D27: 5 | E27: 合成->
C28: お花 | D28: 5 | E28: 前往->
C29: 筆 | D29: 2 | E29: 合成->
C30: サンゴ | D30: 2 | E30: 前往->
C31: 小判 | D31: 150
A32: 团子 | B32: お団子 | C32: 葉っぱ | D32: 1 | E32: 前往->
C33: 桃 | D33: 1 | E33: 前往->
C34: 花の蜜 | D34: 1 | E34: 合成->
C35: お花 | D35: 1 | E35: 前往->
C36: 小判 | D36: 50
A37: 锄头 | B37: 鍬 | C37: とんかち | D37: 5 | E37: 合成->
C38: 丸太 | D38: 5 | E38: 前往->
C39: 鉄 | D39: 2 | E39: 前往->
C40: 小判 | D40: 150
...

Sheet 材料来源
A1: 中文名 | B1: 材料 | C1: 关卡 | E1: 关卡 | F1: 材料 种类 | G1: 掉落材料 | H1: 注：鉴于第一章的关卡的爆率比第三章关卡高，所以在这里标黄了适合给刀练级的关卡
A2: 粘土 | B2: 粘土 | C2: 2-6 | E2: 无标注的掉落注释信息来源于小红书@Yayoty转载的樱花妹分享 | I2: 掉落概率 | J2: 贡献者
C3: 2-7 | E3: 2-26 | F3: / | G3: 水、花、打火石、树枝、蓬松的毛、带骨肉等等 | H3: 一次性关卡 不完成任务解锁下一张图的话可多次刷素材 | I3: 我发现这关刷资源好用 2-26这是一次性关卡，掉落物很... https://xhslink.cn/o/5O52f1ikM3k 带走口令，来【小红书】发现精彩~
C4: 2-11 | I4: （小红书贡献者ID为空……）
C5: 3-12 | E5: 1-02 | F5: 3 | G5: 水、叶子、桃子 | H5: 水、葉っぱ、桃 | I5: 稳定水、叶子 | J5: Heftig
C6: 3-21 | E6: 1-04 | F6: 5 | G6: 木材、大豆、蓬松的毛、带骨肉、蛋 | H6: 丸太、大豆、ふさふさの毛、骨付き肉、卵 | I6: 高概率毛 | J6: Heftig
A7: 打火石 | B7: 火打ち石 | C7: 2-16 | E7: 1-07 | F7: 3 | G7: 木材、叶子、麦 | H7: 丸太、葉っぱ、麦
C8: 2-22 | E8: 1-09 | F8: 3 | G8: 大豆、水、桃子 | H8: 大豆、水、桃
C9: 3-19 | E9: 1-11 | F9: 3 | G9: 蓬松的毛、麦、带骨肉 | H9: ふさふさの毛、麦、骨付き肉
C10: 3-31 | E10: 1-12 | F10: 5 | G10: 木材、兽牙、蓬松的毛、虎皮、麦 | H10: 丸太、獣の牙、ふさふさの毛、トラの毛皮、麦 | I10: 高概率毛 | J10: Heftig
A11: 木材 | B11: 丸太 | C11: 1-4 | E11: 1-13 | F11: 3 | G11: 大豆、叶子、蛋 | H11: 大豆、葉っぱ、卵
C12: 1-7 | E12: 1-17 | F12: 4 | G12: 大豆、水、鬼的角、虎皮 | H12: 大豆、水、鬼のツノ、トラの毛皮 | I12: 稳定水和豆，鬼角稀少 | J12: Piya
C13: 1-12 | E13: 2-02 | F13: 2 | G13: 大米、大豆 | H13: お米、大豆
C14: 2-16 | E14: 2-05 | F14: 2 | G14: 铁、带骨肉 | H14: 鉄、骨付き肉 | I14: 必掉铁
C15: 2-25 | E15: 2-06 | F15: 4 | G15: 粘土、树枝、水、鱼 | H15: 粘土、木の枝、水、お魚 | I15: 必掉鱼 | J15: 乌七
C16: 3-12 | E16: 2-07 | F16: 4 | G16: 粘土、水、油、鱼 | H16: 粘土、水、油、お魚 | I16: 必掉鱼 | J16: 乌七
A17: 兽牙 | B17: 獣の牙 | C17: 1-12 | E17: 2-11 | F17: 3 | G17: 粘土、水、鱼 | H17: 粘土、水、お魚 | I17: 还是必掉鱼 | J17: 乌七
C18: 2-27 | E18: 2-12 | F18: 5 | G18: 铁、大米、大豆、鱼、蛋 | H18: 鉄、お米、大豆、お魚、卵
C19: 3-26 | E19: 2-16 | F19: 4 | G19: 打火石、木材、树枝、骰子 | H19: 火打ち石、丸太、木の枝、サイコロ
A20: 铁 | B20: 鉄 | C20: 2-5 | E20: 2-19 | F20: 3 | G20: 大米、蓬松的毛、带骨肉 | H20: お米、ふさふさの毛、骨付き肉
C21: 2-12 | E21: 2-22 | F21: 4 | G21: 打火石、树枝、御影石、蜡烛 | H21: 火打ち石、木の枝、みかげ石、ろうそく | K21: 感受到了怨念和痛苦
C22: 3-4 | E22: 2-24 | F22: 4 | G22: 御影石、骰子、蜡烛、鱼 | H22: みかげ石、サイコロ、ろうそく、お魚 | I22: 多骰子 | J22: 风骅
C23: 3-7 | E23: 2-25 | F23: 3 | G23: 木材、树枝、花 | H23: 丸太、木の枝、お花 | I23: 砍断6根木材必掉木材，多树枝 | J23: zznatsu
C24: 3-33 | E24: 2-27 | F24: 4 | G24: 兽牙、水、鬼的角、虎皮 | H24: 獣の牙、水、鬼のツノ、トラの毛皮
A25: 鳞片 | B25: ウロコ | C25: 3-24 | E25: 2-29 | F25: 2 | G25: 蓬松的毛、发绳 | H25: ふさふさの毛、元結
C26: 3-35 | E26: 3-02 | F26: 5 | G26: 大米、盐、水、蚌、海带 | H26: お米、塩、水、真珠貝、昆布
A27: 大米 | B27: お米 | C27: 2-2 | E27: 3-04 | F27: 5 | G27: 铁、御影石、蚌、油、螺丝 | H27: 鉄、みかげ石、真珠貝、油、ネジ
C28: 2-12 | E28: 3-07 | F28: 6 | G28: 铁、大米、御影石、花、桃子、蚌 | H28: 鉄、お米、みかげ石、お花、桃、真珠貝
C29: 2-19 | E29: 3-09 | F29: 4 | G29: 大豆、蚌、手旗、麦 | H29: 大豆、真珠貝、手旗、麦
C30: 3-2 | E30: 3-12 | F30: 4 | G30: 粘土、木材、树枝、手旗 | H30: 粘土、丸太、木の枝、手旗 | I30: 高概率树枝
C31: 3-7 | E31: 3-14 | F31: 3 | G31: 手旗、虎皮、骰子 | H31: 手旗、トラの毛皮、サイコロ | I31: 高概率骰子
C32: 3-26 | E32: 3-17 | F32: 6 | G32: 大豆、水、珊瑚、蚌、蟹钳、海带 | H32: 大豆、水、サンゴ、真珠貝、カニのはさみ、昆布
A33: 盐 | B33: 塩 | C33: 3-2 | E33: 3-19 | F33: 2 | G33: 打火石、蜡烛 | H33: 火打ち石、ろうそく | I33: boss高概率/必掉打火石 | J33: Heftig
C34: 3-24 | E34: 3-21 | F34: 4 | G34: 粘土、御影石、桃子、蟹钳 | H34: 粘土、みかげ石、桃、カニのはさみ | I34: 高概率黏土 | J34: 乌七
C35: 3-26 | E35: 3-24 | F35: 6 | G35: 鳞片、盐、珊瑚、叶子、桃子、鱼 | H35: ウロコ、塩、サンゴ、葉っぱ、桃、お魚 | I35: 稳定叶子，高概率叶子x2和盐 | J35: piya
C36: 3-29 | E36: 3-26 | F36: 5 | G36: 兽牙、大米、盐、水、海带
C37: 3-33 | E37: 3-29 | F37: 5 | G37: 盐、御影石、珊瑚、蟹钳、海带 | H37: 塩、みかげ石、サンゴ、カニのはさみ、昆布
C38: 3-35 | E38: 3-31 | F38: 2 | G38: 打火石、蜡烛 | H38: 獣の牙、お米、塩、水、昆布 | I38: 打火石几乎必掉
A39: 大豆 | B39: 大豆 | C39: 1-4 | E39: 3-33 | F39: 4 | G39: 铁、盐、油、螺丝 | H39: 鉄、塩、油、ネジ
C40: 1-13 | E40: 3-35 | F40: 4 | G40: 鳞片、盐、珊瑚、羽衣 | H40: ウロコ、塩、サンゴ、羽衣
...

Sheet 关卡统计（透视表用）
A1: 中文名 | B1: 材料 | C1: 关卡 | E1: 关卡 | F1: 计数项:材料 | G1: 掉落材料 | H1: 注：鉴于第一章的关卡的爆率比第三章关卡高，所以在这里标黄了适合给刀练级的关卡
A2: 粘土 | B2: 粘土 | C2: 2-6 | E2: 3-17 | F2: 6 | G2: {==_xlfn.TEXTJOIN("、",TRUE,_xlfn._xlws.FILTER($B$2:$B$200,$C$2:$C$200=E2))} -> 大豆、水、サンゴ、真珠貝、カニのはさみ、昆布
A3: 粘土 | B3: 粘土 | C3: 2-7 | E3: 3-7 | F3: 6 | G3: {==_xlfn.TEXTJOIN("、",TRUE,_xlfn._xlws.FILTER($B$2:$B$200,$C$2:$C$200=E3))} -> 鉄、お米、みかげ石、お花、桃、真珠貝
A4: 粘土 | B4: 粘土 | C4: 2-11 | E4: 3-24 | F4: 6 | G4: {==_xlfn.TEXTJOIN("、",TRUE,_xlfn._xlws.FILTER($B$2:$B$200,$C$2:$C$200=E4))} -> ウロコ、塩、サンゴ、葉っぱ、桃、お魚
A5: 粘土 | B5: 粘土 | C5: 3-12 | E5: 3-4 | F5: 5 | G5: {==_xlfn.TEXTJOIN("、",TRUE,_xlfn._xlws.FILTER($B$2:$B$200,$C$2:$C$200=E5))} -> 鉄、みかげ石、真珠貝、油、ネジ
A6: 粘土 | B6: 粘土 | C6: 3-21 | E6: 1-12 | F6: 5 | G6: {==_xlfn.TEXTJOIN("、",TRUE,_xlfn._xlws.FILTER($B$2:$B$200,$C$2:$C$200=E6))} -> 丸太、獣の牙、ふさふさの毛、トラの毛皮、麦
A7: 打火石 | B7: 火打ち石 | C7: 2-16 | E7: 3-26 | F7: 5 | G7: {==_xlfn.TEXTJOIN("、",TRUE,_xlfn._xlws.FILTER($B$2:$B$200,$C$2:$C$200=E7))} -> 獣の牙、お米、塩、水、昆布
A8: 打火石 | B8: 火打ち石 | C8: 2-22 | E8: 3-2 | F8: 5 | G8: {==_xlfn.TEXTJOIN("、",TRUE,_xlfn._xlws.FILTER($B$2:$B$200,$C$2:$C$200=E8))} -> お米、塩、水、真珠貝、昆布
A9: 打火石 | B9: 火打ち石 | C9: 3-19 | E9: 1-4 | F9: 5 | G9: {==_xlfn.TEXTJOIN("、",TRUE,_xlfn._xlws.FILTER($B$2:$B$200,$C$2:$C$200=E9))} -> 丸太、大豆、ふさふさの毛、骨付き肉、卵
A10: 打火石 | B10: 火打ち石 | C10: 3-31 | E10: 3-29 | F10: 5 | G10: {==_xlfn.TEXTJOIN("、",TRUE,_xlfn._xlws.FILTER($B$2:$B$200,$C$2:$C$200=E10))} -> 塩、みかげ石、サンゴ、カニのはさみ、昆布
A11: 木材 | B11: 丸太 | C11: 1-4 | E11: 2-12 | F11: 5 | G11: {==_xlfn.TEXTJOIN("、",TRUE,_xlfn._xlws.FILTER($B$2:$B$200,$C$2:$C$200=E11))} -> 鉄、お米、大豆、お魚、卵
A12: 木材 | B12: 丸太 | C12: 1-7 | E12: 3-12 | F12: 4 | G12: {==_xlfn.TEXTJOIN("、",TRUE,_xlfn._xlws.FILTER($B$2:$B$200,$C$2:$C$200=E12))} -> 粘土、丸太、木の枝、手旗
A13: 木材 | B13: 丸太 | C13: 1-12 | E13: 2-24 | F13: 4 | G13: {==_xlfn.TEXTJOIN("、",TRUE,_xlfn._xlws.FILTER($B$2:$B$200,$C$2:$C$200=E13))} -> みかげ石、サイコロ、ろうそく、お魚
... A37: 盐 | B37: 塩 | C37: 3-33 | E37: 3-31 | F37: 2 | G37: {==_xlfn.TEXTJOIN("、",TRUE,_xlfn._xlws.FILTER($B$2:$B$200,$C$2:$C$200=E37))} -> 火打ち石、ろうそく
A38: 盐 | B38: 塩 | C38: 3-35 | G38: ==_xlfn.TEXTJOIN("、",TRUE,_xlfn._xlws.FILTER($B$2:$B$200,$C$2:$C$200=E38))
A39: 大豆 | B39: 大豆 | C39: 1-4 | E39: 总计 | F39: 138
A40: 大豆 | B40: 大豆 | C40: 1-13
A41: 大豆 | B41: 大豆 | C41: 1-17
A42: 大豆 | B42: 大豆 | C42: 1-9
A43: 大豆 | B43: 大豆 | C43: 2-2
A44: 大豆 | B44: 大豆 | C44: 2-12
A45: 大豆 | B45: 大豆 | C45: 3-9
A46: 大豆 | B46: 大豆 | C46: 3-17
A47: 树枝 | B47: 木の枝 | C47: 2-6
A48: 树枝 | B48: 木の枝 | C48: 2-16
A49: 树枝 | B49: 木の枝 | C49: 2-22
A50: 树枝 | B50: 木の枝 | C50: 2-25
A51: 树枝 | B51: 木の枝 | C51: 3-12
... A139: 羽衣 | B139: 羽衣 | C139: 3-35

Sheet 其他工具
A2: 刀消养成计算器 | B2: https://sotosakiyuuko.github.io/pazugiri-calculator/
A4: 全部角色奥义、绘马预览 26.9.28 | B4: 刀剑消消乐角色奥义及绘马特效 那个角色预览bug怎么还... https://xhslink.cn/o/4IKvakTtmP4 先复制一下，再到【小红书】打开查看笔记。 | C4: 如果求到作者授权就新开一页把图片都贴进来可以吗 | G4: 我试试 | H4: 我之前发了评论申请作者没理我TWT
A5: 刀消素材掉落 概率统计 | B5: 【搬运】刀剑乱舞消消乐材料掉落规律 上推特发现有yhm... https://xhslink.cn/o/8iMa8Q9jG2g 拷走文字，去【小红书】探索这篇笔记~
B6: 我发现这关刷资源好用 2-26这是一次性关卡，掉落物很... https://xhslink.cn/o/5O52f1ikM3k 带走口令，来【小红书】发现精彩~
A8: 刀消素材掉落查找工具 | B8: https://airrodsushi.wpcomstaging.com/自用消消樂素材存檔/
A9: 本表格统一性校验工具2025.9.28（也直观看原材料、合成物品的中日对照表） | B9: https://haruhito-shio.github.io/touken-check/?v=1 | G9: 太厉害了………………
A10: 多功能材料计算器v2.2.0 | B10: https://haruhito-shio.github.io/touken-puzzle-tool/ 碎碎念：希望后续格式不要大改吧（ 数据已更新至9.30表格版本 | C10: 练刀材料自动计算，空值提示 | D10: 背包库存管理，查看材料缺口 | E10: 材料刷取关卡快速查询 | G10: 太厉害了………………【跪下
C11: 合成拆解，统计材料与小判消耗 | D11: 多选批量操作，数据导出备份 | E11: 彩蛋：本丸今日运势，每日抽取运势事件
A13: 活动信息 | B13: 风骅：自用，不懂日语可能有错，无特殊标注都是累计完成 | G13: 掉落材料
A14: LV10红鬼 | B14: 发现是循环任务并非玩家统一，姑且留着当参考吧 | C14: 攻击50次 | D14: 奥义5次 | E14: 13410伤害 | F14: 杀敌144次 | G14: 蓬松的毛x2、大豆x2 木材x1、更多PT、绘马
C15: 单次连线13个 | D15: 击杀2个boss | E15: 奥义致命一击 | F15: A评级以上
B16: 记得用低等级刀打可以比较少回数完成任务 | C16: 击杀215蓝鬼 | D16: 胜利2局 | E16: 乱舞2次 | F16: 乱舞击杀200饿鬼
B17: 有机会2回完成，一般3回完成 | C17: 合成15个炸弹 | D17: 合成20个lv1+炸弹 | E17: 10次炸弹合体 | F17: 击杀200红鬼
A18: LV12蓝鬼 | B18: 不太清楚lv1+炸弹和1次以上合体包不包括1 | C18: 单局击杀20红鬼 | D18: 单局攻击8次 | E18: 单局奥义1次 | F18: 单局515伤害 | G18: 水x2、叶子x2 麦x1、大豆x1、更多PT、绘马
B19: 单局乱舞/奥义1次应该是至少一次，向上不限 | C19: 单局击杀50饿鬼 | D19: 单局乱舞1次 | E19: 单局乱舞杀60鬼 | F19: 单局合成2次炸弹
C20: 单局合成lv1+炸弹 | D20: 单局1+次炸弹合体 | E20: 击杀215蓝鬼 | F20: 单局击杀30蓝鬼
B21: 有机会1回完成，一般2回完成 | C21: 单局伤害4785 | D21: 击杀230黄鬼 | E21: 单局击杀30黄鬼 | F21: 攻击50次
A22: LV14黄鬼 11200血 | C22: 单局击杀30黄鬼 | D22: 攻击50次 | E22: 奥义5次 | F22: 14934伤害 | G22: 水x2、木材x2 更多PT、绘马
C23: 击杀144饿鬼 | D23: 单次连线13个 | E23: 击杀2个boss | F23: 奥义致命一击
C24: A评级以上 | D24: 单局奥义2次 | E24: 胜利2局 | F24: 乱舞2次
B25: 2回完成 | C25: 乱舞击杀200饿鬼 | D25: 合成15个炸弹 | E25: 合成20个lv1+炸弹 | F25: 10次炸弹合体
A26: LV18大树 12488 | G26: 水x2、鱼x1 更多PT、绘马

Sheet 留言
A1: 感谢各位同事的支持！统计表ver0.1版本已经完善了很多了，这里放一个版留言吧。
A2: 有一些在帖子评论里发截图的同事，我输进表格里并附上了红薯id，直接编辑的同事也可以在贡献者一栏留下自己的名字！
A3: 我还没想好这个表格要是做好了应该怎么保存下去，做wiki或者小程序或者qq机器人都可以吧。反正数据已经开源了，转载的同事记得表明出处
A4: ver0.2版本已经完工！完善了第三章之前所有的关卡掉落。刀男突破材料和材料合成部分还需要完善。
A7: 风骅 | B7: 我基于电脑显示效果整理了表格格式，如果有什么优化建议请留言给我~
B8: 黄改成普是不是好些？毕竟角色本身还有红黄蓝的属性 | F8: 也是哦，那就改吧
B9: 要命了想给刀刀补个充电颜色结果被藤四郎军团击倒了成为了笑话 | F9: 一雪前耻！
B10: 薙刀合成的书写道具数据有误请哪位订正一下
B11: 开一个活动选项卡吗？我先写在其他工具里了 | E11: 活动好像是每个人的任务随机循环，我姑且留下表格方便大家预览掉落和后续怪物
B12: 我手机上能看到格子的注释，如果看不到请告诉我换个方式标注
A14: 交换所
A15: 彩歌仙池子积分交换截止10月5日11:59（10:59）
A16: 记得领每日限时使用的1心体力药（我一定不是唯一忘记领的TWT）
A18: piya 薙刀合成的书写道具数据我给补充了。以及，这个表是可以多人填写吗……？
A19: 不要在1-17刷鬼角……我刷到了80多的水，0个鬼角掉落。不过1-17稳定掉水+豆，各自有俩的概率很高
A20: ⬆️风骅：感谢！目前还没有人捣乱所以作者同事还开着权限，我发现能编辑的时候也很震惊（总之猛猛编辑了）。1-17的掉落说明已经加入备注
A21: piya 刀男所需材料的锹和锄头是同一个材料吧，感觉可以统一一个名字（
A22: ⬆️风骅：改完了❤
A23: piya 材料来源标写混了：3-12的“多毛”以外的信息是3-17，多毛我不知道是哪位同事备注的（
A24: ⬆️风骅：看窜行了对不起！已修改【咽气】等下是3-17还是1-17，果然这个排版会引人疑问是吗——————
A27: 风骅：三色绘具是消耗品吗？？？？？哪里掉啊？？？？？
A28: ⬆️文州：目前只有三章主线完成后红黄蓝各给一个+活跃度pass基础款能攒出2个红绘具，所以理论上现在最多练出5把35级（根本不够（气
... A42: ⬆️年下阴角激推：谁说不是呢，，同为命苦之人（可恶啊——话说有看到说掉落物跟boss有关desu
